Workbook

Sheet 2024
A1: categoria | B1: Segmento | C1: isBodySplash
A2: T. Perfumaria e Colônias | B2: Total | C2: Não
A3: T. Subcategorías | B3: Total | C3: Não
A4: T. Feminino | B4: Total | C4: Não
A5: T. Masculino | B5: Total | C5: Não
A6: T. Infantil | B6: Total | C6: Não
A7: T. Embalagem | B7: Total | C7: Não
A8: Refil | B8: Total | C8: Não
A9: Nao Refil | B9: Total | C9: Não
A10: T. Conteudos | B10: Total | C10: Não
A11: Ate 10 Ml. | B11: Total | C11: Não
A12: 11 A 30 Ml. | B12: Total | C12: Não
... A545: Outros Fabricantes Infantil-Cli | B545: Infantil | C545: Não

Sheet 2025
A1: Região | B1: Segmento | C1: Fabricante | D1: Marca | E1: Classificação | F1: Cód. | G1: Marcas | H1: IsBodySplash
A2: T. Brasil | B2: Total | C2: Total | D2: Total | E2: Total | F2: 1 | G2: T. Perfumaria | H2: Não
A3: T. Brasil | B3: Total | C3: Total | D3: Total | E3: Total | F3: 2 | G3: T. Subcategorias | H3: Não
A4: T. Brasil | B4: Total | C4: Total | D4: Total | E4: Total | F4: 2.1 | G4: Feminino | H4: Não
A5: T. Brasil | B5: Total | C5: Total | D5: Total | E5: Total | F5: 2.2 | G5: Masculino | H5: Não
A6: T. Brasil | B6: Total | C6: Total | D6: Total | E6: Total | F6: 2.3 | G6: Infantil | H6: Não
A7: T. Brasil | B7: Total | C7: Total | D7: Total | E7: Total | F7: 2.4 | G7: Unisex | H7: Não
A8: T. Brasil | B8: Total | C8: Total | D8: Total | E8: Total | F8: 3 | G8: T. Embalagem | H8: Não
A9: T. Brasil | B9: Total | C9: Total | D9: Total | E9: Total | F9: 3.1 | G9: Refil | H9: Não
A10: T. Brasil | B10: Total | C10: Total | D10: Total | E10: Total | F10: 3.2 | G10: Não Refil | H10: Não
A11: T. Brasil | B11: Total | C11: Total | D11: Total | E11: Total | F11: 4 | G11: T. Conteudos | H11: Não
A12: T. Brasil | B12: Total | C12: Total | D12: Total | E12: Total | F12: 4.1 | G12: Ate 10 Ml. | H12: Não
A13: T. Brasil | B13: Total | C13: Total | D13: Total | E13: Total | F13: 4.2 | G13: 11 A 30 Ml. | H13: Não
A14: T. Brasil | B14: Total | C14: Total | D14: Total | E14: Total | F14: 4.3 | G14: 31 A 50 Ml. | H14: Não
A15: T. Brasil | B15: Total | C15: Total | D15: Total | E15: Total | F15: 4.4 | G15: 51 A 75 Ml. | H15: Não
A16: T. Brasil | B16: Total | C16: Total | D16: Total | E16: Total | F16: 4.5 | G16: 76 A 100 Ml. | H16: Não
A17: T. Brasil | B17: Total | C17: Total | D17: Total | E17: Total | F17: 4.6 | G17: 101 A 150 Ml. | H17: Não
A18: T. Brasil | B18: Total | C18: Total | D18: Total | E18: Total | F18: 4.7 | G18: 151 A 200 Ml. | H18: Não
A19: T. Brasil | B19: Total | C19: Total | D19: Total | E19: Total | F19: 4.8 | G19: 201 A 300 Ml. | H19: Não
A20: T. Brasil | B20: Total | C20: Total | D20: Total | E20: Total | F20: 4.9 | G20: 301 A 400 Ml. | H20: Não
A21: T. Brasil | B21: Total | C21: Total | D21: Total | E21: Total | F21: 4.10 | G21: 401 A 500 Ml. | H21: Não
A22: T. Brasil | B22: Total | C22: Total | D22: Total | E22: Total | F22: 4.11 | G22: 501 Ml. Ou Mais | H22: Não
A23: T. Brasil | B23: Total | C23: Total | D23: Total | E23: Total | F23: 4.12 | G23: Outras Embalagens ML | H23: Não
A24: T. Brasil | B24: Total | C24: Total | D24: Total | E24: Total | F24: 5 | G24: T. Fabricantes | H24: Não
A25: T. Brasil | B25: Total | C25: P&G | D25: P&G | E25: Fabricante | F25: 5.1 | G25: T. Procter&Gamble | H25: Não
A26: T. Brasil | B26: Total | C26: Boticário | D26: Boticário | E26: Fabricante | F26: 5.2 | G26: T. Grupo Boticario | H26: Não
A27: T. Brasil | B27: Total | C27: Boticário | D27: Boticário | E27: Marca | F27: 5.2.1 | G27: T. O Boticario | H27: Não
A28: T. Brasil | B28: Total | C28: Boticário | D28: Eudora | E28: Marca | F28: 5.2.2 | G28: T. Eudora | H28: Não
A29: T. Brasil | B29: Total | C29: Boticário | D29: Quem Disse Berenice | E29: Marca | F29: 5.2.3 | G29: T. Quem Disse Berenice? | H29: Não
A30: T. Brasil | B30: Total | C30: O. U. I | D30: O. U. I | E30: Fabricante | F30: 5.2.4 | G30: T. O.U.i | H30: Não
A31: T. Brasil | B31: Total | C31: Natura&CO | D31: Natura&CO | E31: Fabricante | F31: 5.3 | G31: Natura&CO | H31: Não
A32: T. Brasil | B32: Total | C32: Natura | D32: Natura | E32: Fabricante | F32: 5.3.1 | G32: Natura + Avon | H32: Não
A33: T. Brasil | B33: Total | C33: Natura | D33: Avon | E33: Marca | F33: 5.3.1.1 | G33: T. Avon | H33: Não
A34: T. Brasil | B34: Total | C34: Natura | D34: Natura | E34: Marca | F34: 5.3.1.2 | G34: T. Natura | H34: Não
A35: T. Brasil | B35: Total | C35: Kenvue | D35: Kenvue | E35: Fabricante | F35: 5.4 | G35: T. Kenvue | H35: Não
A36: T. Brasil | B36: Total | C36: Hinode | D36: Hinode | E36: Fabricante | F36: 5.5 | G36: T. Hinode | H36: Não
... A60: T. Brasil | B60: Total | C60: Outros Fabricantes | D60: Outros Fabricante | E60: Outros Fabricante | F60: 5.26 | G60: T. Outros Fabricantes | H60: Não
A61: T. Brasil | B61: Total | C61: Total | D61: Total | E61: Total | F61: 6 | G61: T. Segmentação | H61: Não
A62: T. Brasil | B62: Feminino | C62: Total | D62: Total | E62: Total | F62: 6.1 | G62: T. Col. Feminina-Cf | H62: =VLOOKUP(G62,'2024'!$A$1:$C$545,3,0) -> Não
A63: T. Brasil | B63: Feminino | C63: Total | D63: Total | E63: Total | F63: 6.1.1 | G63: Importados-Cf | H63: Não
...
