Workbook

Sheet 2024
A1: categoria | B1: hexa
A2: 101 A 150 Ml. | B2: #DDADD6
A3: 11 A 30 Ml. | B3: #D07ACC
A4: 151 A 200 Ml. | B4: #E0B7D9
A5: 201 A 300 Ml. | B5: #E3C0DB
A6: 300km/H Eletric-Cm | B6: #EEDC82
A7: 300km/H Intense-Cm | B7: #EEE8CD
A8: 300km/H Max Turbo-Cm | B8: #EEDC82
A9: 300km/H Nitro-Cm | B9: #FFFACD
A10: 300km/H Trad.-Cm | B10: #E2D3A6
A11: 300KM/H-Cm | B11: #F0E68C
A12: 301 A 400 Ml. | B12: #E6C8DE
... A545: Zaad-Cm | B545: #58A47B

Sheet 2025
A1: Região | B1: Fabricante | C1: Marca | D1: Classificação | E1: Marcas | F1: hexa | G1: Cor
A2: T. Brasil | B2: Total | C2: Total | D2: Total | E2: 101 A 150 Ml. | F2: =VLOOKUP(E2,'2024'!$A$2:$B$545,2,FALSE) -> #DDADD6
A3: T. Brasil | B3: Total | C3: Total | D3: Total | E3: 11 A 30 Ml. | F3: =VLOOKUP(E3,'2024'!$A$2:$B$545,2,FALSE) -> #D07ACC
A4: T. Brasil | B4: Total | C4: Total | D4: Total | E4: 151 A 200 Ml. | F4: =VLOOKUP(E4,'2024'!$A$2:$B$545,2,FALSE) -> #E0B7D9
A5: T. Brasil | B5: Total | C5: Total | D5: Total | E5: 201 A 300 Ml. | F5: =VLOOKUP(E5,'2024'!$A$2:$B$545,2,FALSE) -> #E3C0DB
A6: T. Brasil | B6: Natura | C6: Avon | D6: Variante | E6: 300km/H Eletric-Cm | F6: =VLOOKUP(E6,'2024'!$A$2:$B$545,2,FALSE) -> #EEDC82
A7: T. Brasil | B7: Natura | C7: Avon | D7: Variante | E7: 300km/H Gamer-Cm | F7: #FFD700
A8: T. Brasil | B8: Natura | C8: Avon | D8: Variante | E8: 300km/H Intense-Cm | F8: =VLOOKUP(E8,'2024'!$A$2:$B$545,2,FALSE) -> #EEE8CD
A9: T. Brasil | B9: Natura | C9: Avon | D9: Variante | E9: 300km/H Max Turbo-Cm | F9: =VLOOKUP(E9,'2024'!$A$2:$B$545,2,FALSE) -> #EEDC82
A10: T. Brasil | B10: Natura | C10: Avon | D10: Variante | E10: 300km/H Nitro-Cm | F10: =VLOOKUP(E10,'2024'!$A$2:$B$545,2,FALSE) -> #FFFACD
A11: T. Brasil | B11: Natura | C11: Avon | D11: Variante | E11: 300km/H Surfer-Cm | F11: #EEDC82
A12: T. Brasil | B12: Natura | C12: Avon | D12: Variante | E12: 300km/H Trad.-Cm | F12: =VLOOKUP(E12,'2024'!$A$2:$B$545,2,FALSE) -> #E2D3A6
A13: T. Brasil | B13: Natura | C13: Avon | D13: Sub Marca | E13: 300km/H-Cm | F13: =VLOOKUP(E13,'2024'!$A$2:$B$545,2,FALSE) -> #F0E68C
A14: T. Brasil | B14: Total | C14: Total | D14: Total | E14: 301 A 400 Ml. | F14: =VLOOKUP(E14,'2024'!$A$2:$B$545,2,FALSE) -> #E6C8DE
A15: T. Brasil | B15: Total | C15: Total | D15: Total | E15: 31 A 50 Ml. | F15: =VLOOKUP(E15,'2024'!$A$2:$B$545,2,FALSE) -> #D489CE
A16: T. Brasil | B16: Total | C16: Total | D16: Total | E16: 401 A 500 Ml. | F16: =VLOOKUP(E16,'2024'!$A$2:$B$545,2,FALSE) -> #E8D1E0
A17: T. Brasil | B17: Total | C17: Total | D17: Total | E17: 501 Ml. Ou Mais | F17: =VLOOKUP(E17,'2024'!$A$2:$B$545,2,FALSE) -> #EBD9E3
A18: T. Brasil | B18: Total | C18: Total | D18: Total | E18: 51 A 75 Ml. | F18: =VLOOKUP(E18,'2024'!$A$2:$B$545,2,FALSE) -> #D796D1
A19: T. Brasil | B19: Total | C19: Total | D19: Total | E19: 76 A 100 Ml. | F19: =VLOOKUP(E19,'2024'!$A$2:$B$545,2,FALSE) -> #DAA2D4
A20: T. Brasil | B20: Natura | C20: Avon | D20: Variante | E20: AA Alfazema-Cf | F20: =VLOOKUP(E20,'2024'!$A$2:$B$545,2,FALSE) -> #F1E2C7
A21: T. Brasil | B21: Natura | C21: Avon | D21: Variante | E21: AA Ameixa-Cf | F21: =VLOOKUP(E21,'2024'!$A$2:$B$545,2,FALSE) -> #D1C27B
A22: T. Brasil | B22: Natura | C22: Avon | D22: Variante | E22: AA Baby Smell - Cf | F22: =VLOOKUP(E22,'2024'!$A$2:$B$545,2,FALSE) -> #E8D9B4
A23: T. Brasil | B23: Natura | C23: Avon | D23: Variante | E23: AA Blue Lotus-Cf | F23: =VLOOKUP(E23,'2024'!$A$2:$B$545,2,FALSE) -> #D4C585
... A28: T. Brasil | B28: Natura | C28: Avon | D28: Variante | E28: AA Lavanda Splash-Cf | F28: =VLOOKUP(E28,'2024'!$A$2:$B$545,2,FALSE) -> #E2D3A6
A29: T. Brasil | B29: Natura | C29: Avon | D29: Variante | E29: AA Melancia-Cf | F29: #E1CCA0
A30: T. Brasil | B30: Natura | C30: Avon | D30: Variante | E30: AA Pitanga | F30: =VLOOKUP(E30,'2024'!$A$2:$B$545,2,FALSE) -> #EBDCBB
A31: T. Brasil | B31: Natura | C31: Avon | D31: Variante | E31: AA Pretty Blue-Cf | F31: =VLOOKUP(E31,'2024'!$A$2:$B$545,2,FALSE) -> #E5D6AE
A32: T. Brasil | B32: Boticário | C32: Boticário | D32: Sub Marca | E32: Accordes-Cf | F32: =VLOOKUP(E32,'2024'!$A$2:$B$545,2,FALSE) -> #00FF00
A33: T. Brasil | B33: Boticário | C33: Boticário | D33: Sub Marca | E33: Acqua Fresca-Cf | F33: =VLOOKUP(E33,'2024'!$A$2:$B$545,2,FALSE) -> #00FE88
A34: T. Brasil | B34: Natura | C34: Natura | D34: Variante | E34: Aguas Jabuticaba-Cf | F34: =VLOOKUP(E34,'2024'!$A$2:$B$545,2,FALSE) -> #D5741B
A35: T. Brasil | B35: Natura | C35: Natura | D35: Variante | E35: Aguas Lírio-Cf | F35: =VLOOKUP(E35,'2024'!$A$2:$B$545,2,FALSE) -> #E69016
A36: T. Brasil | B36: Natura | C36: Natura | D36: Variante | E36: Aguas Violeta-Cf | F36: =VLOOKUP(E36,'2024'!$A$2:$B$545,2,FALSE) -> #EE9D14
A37: T. Brasil | B37: Boticário | C37: Boticário | D37: Sub Marca | E37: Anni-Cf | F37: =VLOOKUP(E37,'2024'!$A$2:$B$545,2,FALSE) -> #00CD66
A38: T. Brasil | B38: Boticário | C38: Boticário | D38: Variante | E38: Arbo Atlântica-Cm | F38: #71B225
A39: T. Brasil | B39: Boticário | C39: Boticário | D39: Variante | E39: Arbo Botanic-Cm | F39: =VLOOKUP(E39,'2024'!$A$2:$B$545,2,FALSE) -> #7AA228
A40: T. Brasil | B40: Boticário | C40: Boticário | D40: Variante | E40: Arbo Forest-Cm | F40: #7BA27B
A41: T. Brasil | B41: Boticário | C41: Boticário | D41: Variante | E41: Arbo Intenso-Cm | F41: =VLOOKUP(E41,'2024'!$A$2:$B$545,2,FALSE) -> #94C530
A42: T. Brasil | B42: Boticário | C42: Boticário | D42: Variante | E42: Arbo Liberte-Cm | F42: =VLOOKUP(E42,'2024'!$A$2:$B$545,2,FALSE) -> #83AE2A
A43: T. Brasil | B43: Boticário | C43: Boticário | D43: Variante | E43: Arbo Ocean-Cm | F43: =VLOOKUP(E43,'2024'!$A$2:$B$545,2,FALSE) -> #8CB92D
A44: T. Brasil | B44: Boticário | C44: Boticário | D44: Variante | E44: Arbo Puro-Cm | F44: =VLOOKUP(E44,'2024'!$A$2:$B$545,2,FALSE) -> #9DD133
...
